[2024-09-29T17:35:48.820+0000] {local_task_job_runner.py:120} INFO - ::group::Pre task execution logs
[2024-09-29T17:35:48.853+0000] {taskinstance.py:2076} INFO - Dependencies all met for dep_context=non-requeueable deps ti=<TaskInstance: intialization_database.create_database_football_scotland manual__2024-09-29T17:30:03.207213+00:00 [queued]>
[2024-09-29T17:35:48.868+0000] {taskinstance.py:2076} INFO - Dependencies all met for dep_context=requeueable deps ti=<TaskInstance: intialization_database.create_database_football_scotland manual__2024-09-29T17:30:03.207213+00:00 [queued]>
[2024-09-29T17:35:48.869+0000] {taskinstance.py:2306} INFO - Starting attempt 2 of 2
[2024-09-29T17:35:48.887+0000] {taskinstance.py:2330} INFO - Executing <Task(PostgresOperator): create_database_football_scotland> on 2024-09-29 17:30:03.207213+00:00
[2024-09-29T17:35:48.894+0000] {warnings.py:112} WARNING - /home/***/.local/lib/python3.12/site-packages/***/task/task_runner/standard_task_runner.py:61: DeprecationWarning: This process (pid=5433) is multi-threaded, use of fork() may lead to deadlocks in the child.
  pid = os.fork()

[2024-09-29T17:35:48.896+0000] {standard_task_runner.py:63} INFO - Started process 5435 to run task
[2024-09-29T17:35:48.897+0000] {standard_task_runner.py:90} INFO - Running: ['***', 'tasks', 'run', 'intialization_database', 'create_database_football_scotland', 'manual__2024-09-29T17:30:03.207213+00:00', '--job-id', '2876', '--raw', '--subdir', 'DAGS_FOLDER/initialization.py', '--cfg-path', '/tmp/tmpv0qwtt70']
[2024-09-29T17:35:48.898+0000] {standard_task_runner.py:91} INFO - Job 2876: Subtask create_database_football_scotland
[2024-09-29T17:35:48.953+0000] {task_command.py:426} INFO - Running <TaskInstance: intialization_database.create_database_football_scotland manual__2024-09-29T17:30:03.207213+00:00 [running]> on host e78fe06b6548
[2024-09-29T17:35:49.061+0000] {taskinstance.py:2648} INFO - Exporting env vars: AIRFLOW_CTX_DAG_OWNER='***' AIRFLOW_CTX_DAG_ID='intialization_database' AIRFLOW_CTX_TASK_ID='create_database_football_scotland' AIRFLOW_CTX_EXECUTION_DATE='2024-09-29T17:30:03.207213+00:00' AIRFLOW_CTX_TRY_NUMBER='2' AIRFLOW_CTX_DAG_RUN_ID='manual__2024-09-29T17:30:03.207213+00:00'
[2024-09-29T17:35:49.064+0000] {taskinstance.py:430} INFO - ::endgroup::
[2024-09-29T17:35:49.065+0000] {sql.py:276} INFO - Executing: -- SQL script to create a database and schema
CREATE DATABASE football_scotland;

[2024-09-29T17:35:49.074+0000] {base.py:84} INFO - Using connection ID 'football_***_connection' for task execution.
[2024-09-29T17:35:49.084+0000] {base.py:84} INFO - Using connection ID 'football_***_connection' for task execution.
[2024-09-29T17:35:49.089+0000] {sql.py:487} INFO - Running statement: -- SQL script to create a database and schema
CREATE DATABASE football_scotland;
, parameters: None
[2024-09-29T17:35:49.090+0000] {taskinstance.py:441} INFO - ::group::Post task execution logs
[2024-09-29T17:35:49.091+0000] {taskinstance.py:2905} ERROR - Task failed with exception
Traceback (most recent call last):
  File "/home/airflow/.local/lib/python3.12/site-packages/airflow/models/taskinstance.py", line 465, in _execute_task
    result = _execute_callable(context=context, **execute_callable_kwargs)
             ^^^^^^^^^^^^^^^^^^^^^^^^^^^^^^^^^^^^^^^^^^^^^^^^^^^^^^^^^^^^^
  File "/home/airflow/.local/lib/python3.12/site-packages/airflow/models/taskinstance.py", line 432, in _execute_callable
    return execute_callable(context=context, **execute_callable_kwargs)
           ^^^^^^^^^^^^^^^^^^^^^^^^^^^^^^^^^^^^^^^^^^^^^^^^^^^^^^^^^^^^
  File "/home/airflow/.local/lib/python3.12/site-packages/airflow/models/baseoperator.py", line 401, in wrapper
    return func(self, *args, **kwargs)
           ^^^^^^^^^^^^^^^^^^^^^^^^^^^
  File "/home/airflow/.local/lib/python3.12/site-packages/airflow/providers/common/sql/operators/sql.py", line 282, in execute
    output = hook.run(
             ^^^^^^^^^
  File "/home/airflow/.local/lib/python3.12/site-packages/airflow/providers/common/sql/hooks/sql.py", line 435, in run
    self._run_command(cur, sql_statement, parameters)
  File "/home/airflow/.local/lib/python3.12/site-packages/airflow/providers/common/sql/hooks/sql.py", line 492, in _run_command
    cur.execute(sql_statement)
psycopg2.errors.DuplicateDatabase: database "football_scotland" already exists

[2024-09-29T17:35:49.101+0000] {taskinstance.py:1206} INFO - Marking task as FAILED. dag_id=intialization_database, task_id=create_database_football_scotland, run_id=manual__2024-09-29T17:30:03.207213+00:00, execution_date=20240929T173003, start_date=20240929T173548, end_date=20240929T173549
[2024-09-29T17:35:49.116+0000] {standard_task_runner.py:110} ERROR - Failed to execute job 2876 for task create_database_football_scotland (database "football_scotland" already exists
; 5435)
[2024-09-29T17:35:49.151+0000] {local_task_job_runner.py:240} INFO - Task exited with return code 1
[2024-09-29T17:35:49.162+0000] {warnings.py:112} WARNING - /home/***/.local/lib/python3.12/site-packages/***/models/baseoperator.py:1297: AirflowProviderDeprecationWarning: Call to deprecated class PostgresOperator. (Please use `***.providers.common.sql.operators.sql.SQLExecuteQueryOperator`.Also, you can provide `hook_params={'schema': <database>}`.)
  result = cls.__new__(cls)

[2024-09-29T17:35:49.179+0000] {taskinstance.py:3503} INFO - 0 downstream tasks scheduled from follow-on schedule check
[2024-09-29T17:35:49.184+0000] {local_task_job_runner.py:222} INFO - ::endgroup::
