[2024-10-08T11:39:51.533+0000] {local_task_job_runner.py:120} INFO - ::group::Pre task execution logs
[2024-10-08T11:39:51.581+0000] {taskinstance.py:2076} INFO - Dependencies all met for dep_context=non-requeueable deps ti=<TaskInstance: update_database.run_sofascore_scraper manual__2024-10-08T11:39:47.381805+00:00 [queued]>
[2024-10-08T11:39:51.589+0000] {taskinstance.py:2076} INFO - Dependencies all met for dep_context=requeueable deps ti=<TaskInstance: update_database.run_sofascore_scraper manual__2024-10-08T11:39:47.381805+00:00 [queued]>
[2024-10-08T11:39:51.590+0000] {taskinstance.py:2306} INFO - Starting attempt 1 of 2
[2024-10-08T11:39:51.605+0000] {taskinstance.py:2330} INFO - Executing <Task(DockerOperator): run_sofascore_scraper> on 2024-10-08 11:39:47.381805+00:00
[2024-10-08T11:39:51.613+0000] {warnings.py:112} WARNING - /home/***/.local/lib/python3.12/site-packages/***/task/task_runner/standard_task_runner.py:61: DeprecationWarning: This process (pid=69) is multi-threaded, use of fork() may lead to deadlocks in the child.
  pid = os.fork()

[2024-10-08T11:39:51.615+0000] {standard_task_runner.py:63} INFO - Started process 71 to run task
[2024-10-08T11:39:51.616+0000] {standard_task_runner.py:90} INFO - Running: ['***', 'tasks', 'run', 'update_database', 'run_sofascore_scraper', 'manual__2024-10-08T11:39:47.381805+00:00', '--job-id', '3793', '--raw', '--subdir', 'DAGS_FOLDER/update.py', '--cfg-path', '/tmp/tmpo4gbm8iu']
[2024-10-08T11:39:51.617+0000] {standard_task_runner.py:91} INFO - Job 3793: Subtask run_sofascore_scraper
[2024-10-08T11:39:51.679+0000] {task_command.py:426} INFO - Running <TaskInstance: update_database.run_sofascore_scraper manual__2024-10-08T11:39:47.381805+00:00 [running]> on host d0a51eeff5f9
[2024-10-08T11:39:51.810+0000] {taskinstance.py:2648} INFO - Exporting env vars: AIRFLOW_CTX_DAG_OWNER='***' AIRFLOW_CTX_DAG_ID='update_database' AIRFLOW_CTX_TASK_ID='run_sofascore_scraper' AIRFLOW_CTX_EXECUTION_DATE='2024-10-08T11:39:47.381805+00:00' AIRFLOW_CTX_TRY_NUMBER='1' AIRFLOW_CTX_DAG_RUN_ID='manual__2024-10-08T11:39:47.381805+00:00'
[2024-10-08T11:39:51.813+0000] {taskinstance.py:430} INFO - ::endgroup::
[2024-10-08T11:39:51.821+0000] {docker.py:157} ERROR - Failed to establish connection to Docker host unix://var/run/docker.sock: Error while fetching server API version: ('Connection aborted.', FileNotFoundError(2, 'No such file or directory'))
[2024-10-08T11:39:51.821+0000] {taskinstance.py:441} INFO - ::group::Post task execution logs
[2024-10-08T11:39:51.832+0000] {taskinstance.py:2905} ERROR - Task failed with exception
Traceback (most recent call last):
  File "/home/airflow/.local/lib/python3.12/site-packages/airflow/models/taskinstance.py", line 465, in _execute_task
    result = _execute_callable(context=context, **execute_callable_kwargs)
             ^^^^^^^^^^^^^^^^^^^^^^^^^^^^^^^^^^^^^^^^^^^^^^^^^^^^^^^^^^^^^
  File "/home/airflow/.local/lib/python3.12/site-packages/airflow/models/taskinstance.py", line 432, in _execute_callable
    return execute_callable(context=context, **execute_callable_kwargs)
           ^^^^^^^^^^^^^^^^^^^^^^^^^^^^^^^^^^^^^^^^^^^^^^^^^^^^^^^^^^^^
  File "/home/airflow/.local/lib/python3.12/site-packages/airflow/models/baseoperator.py", line 401, in wrapper
    return func(self, *args, **kwargs)
           ^^^^^^^^^^^^^^^^^^^^^^^^^^^
  File "/home/airflow/.local/lib/python3.12/site-packages/airflow/providers/docker/operators/docker.py", line 492, in execute
    if self.force_pull or not self.cli.images(name=self.image):
                              ^^^^^^^^
  File "/home/airflow/.local/lib/python3.12/site-packages/airflow/providers/docker/operators/docker.py", line 362, in cli
    return self.hook.api_client
           ^^^^^^^^^^^^^^^^^^^^
  File "/usr/local/lib/python3.12/functools.py", line 995, in __get__
    val = self.func(instance)
          ^^^^^^^^^^^^^^^^^^^
  File "/home/airflow/.local/lib/python3.12/site-packages/airflow/providers/docker/hooks/docker.py", line 161, in api_client
    raise AirflowException("Failed to establish connection to any given Docker hosts.")
airflow.exceptions.AirflowException: Failed to establish connection to any given Docker hosts.
[2024-10-08T11:39:51.838+0000] {taskinstance.py:1206} INFO - Marking task as UP_FOR_RETRY. dag_id=update_database, task_id=run_sofascore_scraper, run_id=manual__2024-10-08T11:39:47.381805+00:00, execution_date=20241008T113947, start_date=20241008T113951, end_date=20241008T113951
[2024-10-08T11:39:51.853+0000] {standard_task_runner.py:110} ERROR - Failed to execute job 3793 for task run_sofascore_scraper (Failed to establish connection to any given Docker hosts.; 71)
[2024-10-08T11:39:51.869+0000] {local_task_job_runner.py:240} INFO - Task exited with return code 1
[2024-10-08T11:39:51.885+0000] {taskinstance.py:3503} INFO - 0 downstream tasks scheduled from follow-on schedule check
[2024-10-08T11:39:51.887+0000] {local_task_job_runner.py:222} INFO - ::endgroup::
