[2024-10-08T14:28:46.275+0000] {local_task_job_runner.py:120} INFO - ::group::Pre task execution logs
[2024-10-08T14:28:46.327+0000] {taskinstance.py:2076} INFO - Dependencies all met for dep_context=non-requeueable deps ti=<TaskInstance: update_database.run_sofascore_scraper manual__2024-10-08T14:20:23.650666+00:00 [queued]>
[2024-10-08T14:28:46.347+0000] {taskinstance.py:2076} INFO - Dependencies all met for dep_context=requeueable deps ti=<TaskInstance: update_database.run_sofascore_scraper manual__2024-10-08T14:20:23.650666+00:00 [queued]>
[2024-10-08T14:28:46.349+0000] {taskinstance.py:2306} INFO - Starting attempt 1 of 2
[2024-10-08T14:28:46.390+0000] {taskinstance.py:2330} INFO - Executing <Task(BashOperator): run_sofascore_scraper> on 2024-10-08 14:20:23.650666+00:00
[2024-10-08T14:28:46.403+0000] {warnings.py:112} WARNING - /home/***/.local/lib/python3.12/site-packages/***/task/task_runner/standard_task_runner.py:61: DeprecationWarning: This process (pid=87) is multi-threaded, use of fork() may lead to deadlocks in the child.
  pid = os.fork()

[2024-10-08T14:28:46.408+0000] {standard_task_runner.py:63} INFO - Started process 101 to run task
[2024-10-08T14:28:46.415+0000] {standard_task_runner.py:90} INFO - Running: ['***', 'tasks', 'run', 'update_database', 'run_sofascore_scraper', 'manual__2024-10-08T14:20:23.650666+00:00', '--job-id', '3835', '--raw', '--subdir', 'DAGS_FOLDER/update.py', '--cfg-path', '/tmp/tmpv5ua3p6t']
[2024-10-08T14:28:46.418+0000] {standard_task_runner.py:91} INFO - Job 3835: Subtask run_sofascore_scraper
[2024-10-08T14:28:46.536+0000] {task_command.py:426} INFO - Running <TaskInstance: update_database.run_sofascore_scraper manual__2024-10-08T14:20:23.650666+00:00 [running]> on host 1fee8bc549a8
[2024-10-08T14:28:46.713+0000] {taskinstance.py:2648} INFO - Exporting env vars: AIRFLOW_CTX_DAG_OWNER='***' AIRFLOW_CTX_DAG_ID='update_database' AIRFLOW_CTX_TASK_ID='run_sofascore_scraper' AIRFLOW_CTX_EXECUTION_DATE='2024-10-08T14:20:23.650666+00:00' AIRFLOW_CTX_TRY_NUMBER='1' AIRFLOW_CTX_DAG_RUN_ID='manual__2024-10-08T14:20:23.650666+00:00'
[2024-10-08T14:28:46.716+0000] {taskinstance.py:430} INFO - ::endgroup::
[2024-10-08T14:28:46.718+0000] {subprocess.py:63} INFO - Tmp dir root location: /tmp
[2024-10-08T14:28:46.719+0000] {subprocess.py:75} INFO - Running command: ['/usr/bin/bash', '-c', 'docker run -d --name sofascore_scraper_container -v C:/Users/efsta/Desktop/Kostas/Data/football_scotland/***/dags/sofascore_scraper_container/csv:/app/csv kostasmitalloulis/sofascoe_scraper_image_up:latest ']
[2024-10-08T14:28:46.739+0000] {subprocess.py:86} INFO - Output:
[2024-10-08T14:28:46.798+0000] {subprocess.py:93} INFO - docker: Error response from daemon: Conflict. The container name "/sofascore_scraper_container" is already in use by container "f654a3877fa40d95ab878a5ae3300948693f964e194fad101869002d5a524fca". You have to remove (or rename) that container to be able to reuse that name.
[2024-10-08T14:28:46.799+0000] {subprocess.py:93} INFO - See 'docker run --help'.
[2024-10-08T14:28:46.805+0000] {subprocess.py:97} INFO - Command exited with return code 125
[2024-10-08T14:28:46.807+0000] {taskinstance.py:441} INFO - ::group::Post task execution logs
[2024-10-08T14:28:46.827+0000] {taskinstance.py:2905} ERROR - Task failed with exception
Traceback (most recent call last):
  File "/home/airflow/.local/lib/python3.12/site-packages/airflow/models/taskinstance.py", line 465, in _execute_task
    result = _execute_callable(context=context, **execute_callable_kwargs)
             ^^^^^^^^^^^^^^^^^^^^^^^^^^^^^^^^^^^^^^^^^^^^^^^^^^^^^^^^^^^^^
  File "/home/airflow/.local/lib/python3.12/site-packages/airflow/models/taskinstance.py", line 432, in _execute_callable
    return execute_callable(context=context, **execute_callable_kwargs)
           ^^^^^^^^^^^^^^^^^^^^^^^^^^^^^^^^^^^^^^^^^^^^^^^^^^^^^^^^^^^^
  File "/home/airflow/.local/lib/python3.12/site-packages/airflow/models/baseoperator.py", line 401, in wrapper
    return func(self, *args, **kwargs)
           ^^^^^^^^^^^^^^^^^^^^^^^^^^^
  File "/home/airflow/.local/lib/python3.12/site-packages/airflow/operators/bash.py", line 243, in execute
    raise AirflowException(
airflow.exceptions.AirflowException: Bash command failed. The command returned a non-zero exit code 125.
[2024-10-08T14:28:46.840+0000] {taskinstance.py:1206} INFO - Marking task as UP_FOR_RETRY. dag_id=update_database, task_id=run_sofascore_scraper, run_id=manual__2024-10-08T14:20:23.650666+00:00, execution_date=20241008T142023, start_date=20241008T142846, end_date=20241008T142846
[2024-10-08T14:28:46.952+0000] {standard_task_runner.py:110} ERROR - Failed to execute job 3835 for task run_sofascore_scraper (Bash command failed. The command returned a non-zero exit code 125.; 101)
[2024-10-08T14:28:46.994+0000] {local_task_job_runner.py:240} INFO - Task exited with return code 1
[2024-10-08T14:28:47.024+0000] {taskinstance.py:3503} INFO - 0 downstream tasks scheduled from follow-on schedule check
[2024-10-08T14:28:47.031+0000] {local_task_job_runner.py:222} INFO - ::endgroup::
