[2024-10-08T14:17:54.151+0000] {local_task_job_runner.py:120} INFO - ::group::Pre task execution logs
[2024-10-08T14:17:54.178+0000] {taskinstance.py:2076} INFO - Dependencies all met for dep_context=non-requeueable deps ti=<TaskInstance: update_database.pull_docker_image manual__2024-10-08T14:14:08.552864+00:00 [queued]>
[2024-10-08T14:17:54.187+0000] {taskinstance.py:2076} INFO - Dependencies all met for dep_context=requeueable deps ti=<TaskInstance: update_database.pull_docker_image manual__2024-10-08T14:14:08.552864+00:00 [queued]>
[2024-10-08T14:17:54.188+0000] {taskinstance.py:2306} INFO - Starting attempt 1 of 2
[2024-10-08T14:17:54.208+0000] {taskinstance.py:2330} INFO - Executing <Task(BashOperator): pull_docker_image> on 2024-10-08 14:14:08.552864+00:00
[2024-10-08T14:17:54.215+0000] {warnings.py:112} WARNING - /home/***/.local/lib/python3.12/site-packages/***/task/task_runner/standard_task_runner.py:61: DeprecationWarning: This process (pid=519) is multi-threaded, use of fork() may lead to deadlocks in the child.
  pid = os.fork()

[2024-10-08T14:17:54.217+0000] {standard_task_runner.py:90} INFO - Running: ['***', 'tasks', 'run', 'update_database', 'pull_docker_image', 'manual__2024-10-08T14:14:08.552864+00:00', '--job-id', '3826', '--raw', '--subdir', 'DAGS_FOLDER/update.py', '--cfg-path', '/tmp/tmpn86ss4eo']
[2024-10-08T14:17:54.219+0000] {standard_task_runner.py:63} INFO - Started process 521 to run task
[2024-10-08T14:17:54.219+0000] {standard_task_runner.py:91} INFO - Job 3826: Subtask pull_docker_image
[2024-10-08T14:17:54.271+0000] {task_command.py:426} INFO - Running <TaskInstance: update_database.pull_docker_image manual__2024-10-08T14:14:08.552864+00:00 [running]> on host 5e30186d778c
[2024-10-08T14:17:54.369+0000] {taskinstance.py:2648} INFO - Exporting env vars: AIRFLOW_CTX_DAG_OWNER='***' AIRFLOW_CTX_DAG_ID='update_database' AIRFLOW_CTX_TASK_ID='pull_docker_image' AIRFLOW_CTX_EXECUTION_DATE='2024-10-08T14:14:08.552864+00:00' AIRFLOW_CTX_TRY_NUMBER='1' AIRFLOW_CTX_DAG_RUN_ID='manual__2024-10-08T14:14:08.552864+00:00'
[2024-10-08T14:17:54.370+0000] {taskinstance.py:430} INFO - ::endgroup::
[2024-10-08T14:17:54.371+0000] {subprocess.py:63} INFO - Tmp dir root location: /tmp
[2024-10-08T14:17:54.372+0000] {subprocess.py:75} INFO - Running command: ['/usr/bin/bash', '-c', 'docker pull kostasmitalloulis/sofascoe_scraper_image_up:latest']
[2024-10-08T14:17:54.384+0000] {subprocess.py:86} INFO - Output:
[2024-10-08T14:18:09.446+0000] {subprocess.py:93} INFO - Error response from daemon: Get "https://registry-1.docker.io/v2/": net/http: request canceled while waiting for connection (Client.Timeout exceeded while awaiting headers)
[2024-10-08T14:18:09.447+0000] {subprocess.py:97} INFO - Command exited with return code 1
[2024-10-08T14:18:09.448+0000] {taskinstance.py:441} INFO - ::group::Post task execution logs
[2024-10-08T14:18:09.459+0000] {taskinstance.py:2905} ERROR - Task failed with exception
Traceback (most recent call last):
  File "/home/airflow/.local/lib/python3.12/site-packages/airflow/models/taskinstance.py", line 465, in _execute_task
    result = _execute_callable(context=context, **execute_callable_kwargs)
             ^^^^^^^^^^^^^^^^^^^^^^^^^^^^^^^^^^^^^^^^^^^^^^^^^^^^^^^^^^^^^
  File "/home/airflow/.local/lib/python3.12/site-packages/airflow/models/taskinstance.py", line 432, in _execute_callable
    return execute_callable(context=context, **execute_callable_kwargs)
           ^^^^^^^^^^^^^^^^^^^^^^^^^^^^^^^^^^^^^^^^^^^^^^^^^^^^^^^^^^^^
  File "/home/airflow/.local/lib/python3.12/site-packages/airflow/models/baseoperator.py", line 401, in wrapper
    return func(self, *args, **kwargs)
           ^^^^^^^^^^^^^^^^^^^^^^^^^^^
  File "/home/airflow/.local/lib/python3.12/site-packages/airflow/operators/bash.py", line 243, in execute
    raise AirflowException(
airflow.exceptions.AirflowException: Bash command failed. The command returned a non-zero exit code 1.
[2024-10-08T14:18:09.463+0000] {taskinstance.py:1206} INFO - Marking task as UP_FOR_RETRY. dag_id=update_database, task_id=pull_docker_image, run_id=manual__2024-10-08T14:14:08.552864+00:00, execution_date=20241008T141408, start_date=20241008T141754, end_date=20241008T141809
[2024-10-08T14:18:09.477+0000] {standard_task_runner.py:110} ERROR - Failed to execute job 3826 for task pull_docker_image (Bash command failed. The command returned a non-zero exit code 1.; 521)
[2024-10-08T14:18:09.524+0000] {local_task_job_runner.py:240} INFO - Task exited with return code 1
[2024-10-08T14:18:09.548+0000] {taskinstance.py:3503} INFO - 0 downstream tasks scheduled from follow-on schedule check
[2024-10-08T14:18:09.551+0000] {local_task_job_runner.py:222} INFO - ::endgroup::
