[2024-09-29T12:21:16.855+0000] {local_task_job_runner.py:120} INFO - ::group::Pre task execution logs
[2024-09-29T12:21:16.903+0000] {taskinstance.py:2076} INFO - Dependencies all met for dep_context=non-requeueable deps ti=<TaskInstance: intialization_database.create_football_airflow_connection manual__2024-09-29T12:20:40.532258+00:00 [queued]>
[2024-09-29T12:21:16.918+0000] {taskinstance.py:2076} INFO - Dependencies all met for dep_context=requeueable deps ti=<TaskInstance: intialization_database.create_football_airflow_connection manual__2024-09-29T12:20:40.532258+00:00 [queued]>
[2024-09-29T12:21:16.921+0000] {taskinstance.py:2306} INFO - Starting attempt 1 of 1
[2024-09-29T12:21:16.946+0000] {taskinstance.py:2330} INFO - Executing <Task(PythonOperator): create_football_airflow_connection> on 2024-09-29 12:20:40.532258+00:00
[2024-09-29T12:21:16.957+0000] {warnings.py:112} WARNING - /home/***/.local/lib/python3.12/site-packages/***/task/task_runner/standard_task_runner.py:61: DeprecationWarning: This process (pid=1206) is multi-threaded, use of fork() may lead to deadlocks in the child.
  pid = os.fork()

[2024-09-29T12:21:16.959+0000] {standard_task_runner.py:63} INFO - Started process 1208 to run task
[2024-09-29T12:21:16.960+0000] {standard_task_runner.py:90} INFO - Running: ['***', 'tasks', 'run', 'intialization_database', 'create_football_***_connection', 'manual__2024-09-29T12:20:40.532258+00:00', '--job-id', '2810', '--raw', '--subdir', 'DAGS_FOLDER/initialization.py', '--cfg-path', '/tmp/tmpm5truozg']
[2024-09-29T12:21:16.962+0000] {standard_task_runner.py:91} INFO - Job 2810: Subtask create_football_***_connection
[2024-09-29T12:21:17.047+0000] {task_command.py:426} INFO - Running <TaskInstance: intialization_database.create_football_airflow_connection manual__2024-09-29T12:20:40.532258+00:00 [running]> on host e78fe06b6548
[2024-09-29T12:21:17.229+0000] {taskinstance.py:2648} INFO - Exporting env vars: AIRFLOW_CTX_DAG_OWNER='***' AIRFLOW_CTX_DAG_ID='intialization_database' AIRFLOW_CTX_TASK_ID='create_football_***_connection' AIRFLOW_CTX_EXECUTION_DATE='2024-09-29T12:20:40.532258+00:00' AIRFLOW_CTX_TRY_NUMBER='1' AIRFLOW_CTX_DAG_RUN_ID='manual__2024-09-29T12:20:40.532258+00:00'
[2024-09-29T12:21:17.237+0000] {taskinstance.py:430} INFO - ::endgroup::
[2024-09-29T12:21:17.245+0000] {crypto.py:82} WARNING - empty cryptography key - values will not be stored encrypted.
[2024-09-29T12:21:17.275+0000] {taskinstance.py:441} INFO - ::group::Post task execution logs
[2024-09-29T12:21:17.276+0000] {taskinstance.py:2905} ERROR - Task failed with exception
Traceback (most recent call last):
  File "/home/airflow/.local/lib/python3.12/site-packages/sqlalchemy/engine/base.py", line 1910, in _execute_context
    self.dialect.do_execute(
  File "/home/airflow/.local/lib/python3.12/site-packages/sqlalchemy/engine/default.py", line 736, in do_execute
    cursor.execute(statement, parameters)
psycopg2.errors.UniqueViolation: duplicate key value violates unique constraint "connection_conn_id_uq"
DETAIL:  Key (conn_id)=(football_***_connection) already exists.


The above exception was the direct cause of the following exception:

Traceback (most recent call last):
  File "/home/airflow/.local/lib/python3.12/site-packages/airflow/models/taskinstance.py", line 465, in _execute_task
    result = _execute_callable(context=context, **execute_callable_kwargs)
             ^^^^^^^^^^^^^^^^^^^^^^^^^^^^^^^^^^^^^^^^^^^^^^^^^^^^^^^^^^^^^
  File "/home/airflow/.local/lib/python3.12/site-packages/airflow/models/taskinstance.py", line 432, in _execute_callable
    return execute_callable(context=context, **execute_callable_kwargs)
           ^^^^^^^^^^^^^^^^^^^^^^^^^^^^^^^^^^^^^^^^^^^^^^^^^^^^^^^^^^^^
  File "/home/airflow/.local/lib/python3.12/site-packages/airflow/models/baseoperator.py", line 401, in wrapper
    return func(self, *args, **kwargs)
           ^^^^^^^^^^^^^^^^^^^^^^^^^^^
  File "/home/airflow/.local/lib/python3.12/site-packages/airflow/operators/python.py", line 235, in execute
    return_value = self.execute_callable()
                   ^^^^^^^^^^^^^^^^^^^^^^^
  File "/home/airflow/.local/lib/python3.12/site-packages/airflow/operators/python.py", line 252, in execute_callable
    return self.python_callable(*self.op_args, **self.op_kwargs)
           ^^^^^^^^^^^^^^^^^^^^^^^^^^^^^^^^^^^^^^^^^^^^^^^^^^^^^
  File "/opt/airflow/dags/helpers_initialization_dag/create_airflow_connection.py", line 24, in create_airflow_connection
    session.commit()
  File "/home/airflow/.local/lib/python3.12/site-packages/sqlalchemy/orm/session.py", line 1454, in commit
    self._transaction.commit(_to_root=self.future)
  File "/home/airflow/.local/lib/python3.12/site-packages/sqlalchemy/orm/session.py", line 832, in commit
    self._prepare_impl()
  File "/home/airflow/.local/lib/python3.12/site-packages/sqlalchemy/orm/session.py", line 811, in _prepare_impl
    self.session.flush()
  File "/home/airflow/.local/lib/python3.12/site-packages/sqlalchemy/orm/session.py", line 3449, in flush
    self._flush(objects)
  File "/home/airflow/.local/lib/python3.12/site-packages/sqlalchemy/orm/session.py", line 3588, in _flush
    with util.safe_reraise():
  File "/home/airflow/.local/lib/python3.12/site-packages/sqlalchemy/util/langhelpers.py", line 70, in __exit__
    compat.raise_(
  File "/home/airflow/.local/lib/python3.12/site-packages/sqlalchemy/util/compat.py", line 211, in raise_
    raise exception
  File "/home/airflow/.local/lib/python3.12/site-packages/sqlalchemy/orm/session.py", line 3549, in _flush
    flush_context.execute()
  File "/home/airflow/.local/lib/python3.12/site-packages/sqlalchemy/orm/unitofwork.py", line 456, in execute
    rec.execute(self)
  File "/home/airflow/.local/lib/python3.12/site-packages/sqlalchemy/orm/unitofwork.py", line 630, in execute
    util.preloaded.orm_persistence.save_obj(
  File "/home/airflow/.local/lib/python3.12/site-packages/sqlalchemy/orm/persistence.py", line 245, in save_obj
    _emit_insert_statements(
  File "/home/airflow/.local/lib/python3.12/site-packages/sqlalchemy/orm/persistence.py", line 1238, in _emit_insert_statements
    result = connection._execute_20(
             ^^^^^^^^^^^^^^^^^^^^^^^
  File "/home/airflow/.local/lib/python3.12/site-packages/sqlalchemy/engine/base.py", line 1710, in _execute_20
    return meth(self, args_10style, kwargs_10style, execution_options)
           ^^^^^^^^^^^^^^^^^^^^^^^^^^^^^^^^^^^^^^^^^^^^^^^^^^^^^^^^^^^
  File "/home/airflow/.local/lib/python3.12/site-packages/sqlalchemy/sql/elements.py", line 334, in _execute_on_connection
    return connection._execute_clauseelement(
           ^^^^^^^^^^^^^^^^^^^^^^^^^^^^^^^^^^
  File "/home/airflow/.local/lib/python3.12/site-packages/sqlalchemy/engine/base.py", line 1577, in _execute_clauseelement
    ret = self._execute_context(
          ^^^^^^^^^^^^^^^^^^^^^^
  File "/home/airflow/.local/lib/python3.12/site-packages/sqlalchemy/engine/base.py", line 1953, in _execute_context
    self._handle_dbapi_exception(
  File "/home/airflow/.local/lib/python3.12/site-packages/sqlalchemy/engine/base.py", line 2134, in _handle_dbapi_exception
    util.raise_(
  File "/home/airflow/.local/lib/python3.12/site-packages/sqlalchemy/util/compat.py", line 211, in raise_
    raise exception
  File "/home/airflow/.local/lib/python3.12/site-packages/sqlalchemy/engine/base.py", line 1910, in _execute_context
    self.dialect.do_execute(
  File "/home/airflow/.local/lib/python3.12/site-packages/sqlalchemy/engine/default.py", line 736, in do_execute
    cursor.execute(statement, parameters)
sqlalchemy.exc.IntegrityError: (psycopg2.errors.UniqueViolation) duplicate key value violates unique constraint "connection_conn_id_uq"
DETAIL:  Key (conn_id)=(football_***_connection) already exists.

[SQL: INSERT INTO connection (conn_id, conn_type, description, host, schema, login, password, port, is_encrypted, is_extra_encrypted, extra) VALUES (%(conn_id)s, %(conn_type)s, %(description)s, %(host)s, %(schema)s, %(login)s, %(password)s, %(port)s, %(is_encrypted)s, %(is_extra_encrypted)s, %(extra)s) RETURNING connection.id]
[parameters: {'conn_id': 'football_airflow_connection', 'conn_type': 'postgres', 'description': None, 'host': 'postgres', 'schema': 'airflow', 'login': 'airflow', 'password': 'airflow', 'port': '5432', 'is_encrypted': False, 'is_extra_encrypted': False, 'extra': None}]
(Background on this error at: https://sqlalche.me/e/14/gkpj)
[2024-09-29T12:21:17.339+0000] {standard_task_runner.py:110} ERROR - Failed to execute job 2810 for task create_football_***_connection (This Session's transaction has been rolled back due to a previous exception during flush. To begin a new transaction with this Session, first issue Session.rollback(). Original exception was: (psycopg2.errors.UniqueViolation) duplicate key value violates unique constraint "connection_conn_id_uq"
DETAIL:  Key (conn_id)=(football_***_connection) already exists.

[SQL: INSERT INTO connection (conn_id, conn_type, description, host, schema, login, password, port, is_encrypted, is_extra_encrypted, extra) VALUES (%(conn_id)s, %(conn_type)s, %(description)s, %(host)s, %(schema)s, %(login)s, %(password)s, %(port)s, %(is_encrypted)s, %(is_extra_encrypted)s, %(extra)s) RETURNING connection.id]
[parameters: {'conn_id': 'football_airflow_connection', 'conn_type': 'postgres', 'description': None, 'host': 'postgres', 'schema': 'airflow', 'login': 'airflow', 'password': 'airflow', 'port': '5432', 'is_encrypted': False, 'is_extra_encrypted': False, 'extra': None}]
(Background on this error at: https://sqlalche.me/e/14/gkpj) (Background on this error at: https://sqlalche.me/e/14/7s2a); 1208)
[2024-09-29T12:21:17.377+0000] {local_task_job_runner.py:240} INFO - Task exited with return code 1
[2024-09-29T12:21:17.418+0000] {taskinstance.py:3503} INFO - 0 downstream tasks scheduled from follow-on schedule check
[2024-09-29T12:21:17.420+0000] {local_task_job_runner.py:222} INFO - ::endgroup::
