[2024-09-29T17:17:57.476+0000] {local_task_job_runner.py:120} INFO - ::group::Pre task execution logs
[2024-09-29T17:17:57.504+0000] {taskinstance.py:2076} INFO - Dependencies all met for dep_context=non-requeueable deps ti=<TaskInstance: intialization_database.create_database_football_scotland manual__2024-09-29T17:17:20.597703+00:00 [queued]>
[2024-09-29T17:17:57.516+0000] {taskinstance.py:2076} INFO - Dependencies all met for dep_context=requeueable deps ti=<TaskInstance: intialization_database.create_database_football_scotland manual__2024-09-29T17:17:20.597703+00:00 [queued]>
[2024-09-29T17:17:57.517+0000] {taskinstance.py:2306} INFO - Starting attempt 1 of 2
[2024-09-29T17:17:57.533+0000] {taskinstance.py:2330} INFO - Executing <Task(PostgresOperator): create_database_football_scotland> on 2024-09-29 17:17:20.597703+00:00
[2024-09-29T17:17:57.541+0000] {warnings.py:112} WARNING - /home/***/.local/lib/python3.12/site-packages/***/task/task_runner/standard_task_runner.py:61: DeprecationWarning: This process (pid=5134) is multi-threaded, use of fork() may lead to deadlocks in the child.
  pid = os.fork()

[2024-09-29T17:17:57.543+0000] {standard_task_runner.py:63} INFO - Started process 5136 to run task
[2024-09-29T17:17:57.544+0000] {standard_task_runner.py:90} INFO - Running: ['***', 'tasks', 'run', 'intialization_database', 'create_database_football_scotland', 'manual__2024-09-29T17:17:20.597703+00:00', '--job-id', '2851', '--raw', '--subdir', 'DAGS_FOLDER/initialization.py', '--cfg-path', '/tmp/tmpt9tbbi7g']
[2024-09-29T17:17:57.546+0000] {standard_task_runner.py:91} INFO - Job 2851: Subtask create_database_football_scotland
[2024-09-29T17:17:57.595+0000] {task_command.py:426} INFO - Running <TaskInstance: intialization_database.create_database_football_scotland manual__2024-09-29T17:17:20.597703+00:00 [running]> on host e78fe06b6548
[2024-09-29T17:17:57.698+0000] {taskinstance.py:2648} INFO - Exporting env vars: AIRFLOW_CTX_DAG_OWNER='***' AIRFLOW_CTX_DAG_ID='intialization_database' AIRFLOW_CTX_TASK_ID='create_database_football_scotland' AIRFLOW_CTX_EXECUTION_DATE='2024-09-29T17:17:20.597703+00:00' AIRFLOW_CTX_TRY_NUMBER='1' AIRFLOW_CTX_DAG_RUN_ID='manual__2024-09-29T17:17:20.597703+00:00'
[2024-09-29T17:17:57.700+0000] {taskinstance.py:430} INFO - ::endgroup::
[2024-09-29T17:17:57.701+0000] {sql.py:276} INFO - Executing: -- SQL script to create a database and schema
CREATE DATABASE football_scotland;

[2024-09-29T17:17:57.710+0000] {base.py:84} INFO - Using connection ID 'football_***_connection' for task execution.
[2024-09-29T17:17:57.720+0000] {base.py:84} INFO - Using connection ID 'football_***_connection' for task execution.
[2024-09-29T17:17:57.725+0000] {sql.py:487} INFO - Running statement: -- SQL script to create a database and schema
CREATE DATABASE football_scotland;
, parameters: None
[2024-09-29T17:17:57.727+0000] {taskinstance.py:441} INFO - ::group::Post task execution logs
[2024-09-29T17:17:57.728+0000] {taskinstance.py:2905} ERROR - Task failed with exception
Traceback (most recent call last):
  File "/home/airflow/.local/lib/python3.12/site-packages/airflow/models/taskinstance.py", line 465, in _execute_task
    result = _execute_callable(context=context, **execute_callable_kwargs)
             ^^^^^^^^^^^^^^^^^^^^^^^^^^^^^^^^^^^^^^^^^^^^^^^^^^^^^^^^^^^^^
  File "/home/airflow/.local/lib/python3.12/site-packages/airflow/models/taskinstance.py", line 432, in _execute_callable
    return execute_callable(context=context, **execute_callable_kwargs)
           ^^^^^^^^^^^^^^^^^^^^^^^^^^^^^^^^^^^^^^^^^^^^^^^^^^^^^^^^^^^^
  File "/home/airflow/.local/lib/python3.12/site-packages/airflow/models/baseoperator.py", line 401, in wrapper
    return func(self, *args, **kwargs)
           ^^^^^^^^^^^^^^^^^^^^^^^^^^^
  File "/home/airflow/.local/lib/python3.12/site-packages/airflow/providers/common/sql/operators/sql.py", line 282, in execute
    output = hook.run(
             ^^^^^^^^^
  File "/home/airflow/.local/lib/python3.12/site-packages/airflow/providers/common/sql/hooks/sql.py", line 435, in run
    self._run_command(cur, sql_statement, parameters)
  File "/home/airflow/.local/lib/python3.12/site-packages/airflow/providers/common/sql/hooks/sql.py", line 492, in _run_command
    cur.execute(sql_statement)
psycopg2.errors.ActiveSqlTransaction: CREATE DATABASE cannot run inside a transaction block

[2024-09-29T17:17:57.738+0000] {taskinstance.py:1206} INFO - Marking task as UP_FOR_RETRY. dag_id=intialization_database, task_id=create_database_football_scotland, run_id=manual__2024-09-29T17:17:20.597703+00:00, execution_date=20240929T171720, start_date=20240929T171757, end_date=20240929T171757
[2024-09-29T17:17:57.755+0000] {standard_task_runner.py:110} ERROR - Failed to execute job 2851 for task create_database_football_scotland (CREATE DATABASE cannot run inside a transaction block
; 5136)
[2024-09-29T17:17:57.798+0000] {local_task_job_runner.py:240} INFO - Task exited with return code 1
[2024-09-29T17:17:57.822+0000] {taskinstance.py:3503} INFO - 0 downstream tasks scheduled from follow-on schedule check
[2024-09-29T17:17:57.826+0000] {local_task_job_runner.py:222} INFO - ::endgroup::
