[2024-10-08T13:33:18.569+0000] {local_task_job_runner.py:120} INFO - ::group::Pre task execution logs
[2024-10-08T13:33:18.589+0000] {taskinstance.py:2076} INFO - Dependencies all met for dep_context=non-requeueable deps ti=<TaskInstance: update_database.run_sofascore_scraper manual__2024-10-08T13:28:14.646658+00:00 [queued]>
[2024-10-08T13:33:18.599+0000] {taskinstance.py:2076} INFO - Dependencies all met for dep_context=requeueable deps ti=<TaskInstance: update_database.run_sofascore_scraper manual__2024-10-08T13:28:14.646658+00:00 [queued]>
[2024-10-08T13:33:18.600+0000] {taskinstance.py:2306} INFO - Starting attempt 2 of 2
[2024-10-08T13:33:18.618+0000] {taskinstance.py:2330} INFO - Executing <Task(BashOperator): run_sofascore_scraper> on 2024-10-08 13:28:14.646658+00:00
[2024-10-08T13:33:18.625+0000] {warnings.py:112} WARNING - /home/***/.local/lib/python3.12/site-packages/***/task/task_runner/standard_task_runner.py:61: DeprecationWarning: This process (pid=428) is multi-threaded, use of fork() may lead to deadlocks in the child.
  pid = os.fork()

[2024-10-08T13:33:18.627+0000] {standard_task_runner.py:63} INFO - Started process 430 to run task
[2024-10-08T13:33:18.627+0000] {standard_task_runner.py:90} INFO - Running: ['***', 'tasks', 'run', 'update_database', 'run_sofascore_scraper', 'manual__2024-10-08T13:28:14.646658+00:00', '--job-id', '3811', '--raw', '--subdir', 'DAGS_FOLDER/update.py', '--cfg-path', '/tmp/tmpxpl_krns']
[2024-10-08T13:33:18.629+0000] {standard_task_runner.py:91} INFO - Job 3811: Subtask run_sofascore_scraper
[2024-10-08T13:33:18.673+0000] {task_command.py:426} INFO - Running <TaskInstance: update_database.run_sofascore_scraper manual__2024-10-08T13:28:14.646658+00:00 [running]> on host 0152ac35a8a1
[2024-10-08T13:33:18.754+0000] {taskinstance.py:2648} INFO - Exporting env vars: AIRFLOW_CTX_DAG_OWNER='***' AIRFLOW_CTX_DAG_ID='update_database' AIRFLOW_CTX_TASK_ID='run_sofascore_scraper' AIRFLOW_CTX_EXECUTION_DATE='2024-10-08T13:28:14.646658+00:00' AIRFLOW_CTX_TRY_NUMBER='2' AIRFLOW_CTX_DAG_RUN_ID='manual__2024-10-08T13:28:14.646658+00:00'
[2024-10-08T13:33:18.756+0000] {taskinstance.py:430} INFO - ::endgroup::
[2024-10-08T13:33:18.757+0000] {subprocess.py:63} INFO - Tmp dir root location: /tmp
[2024-10-08T13:33:18.758+0000] {subprocess.py:75} INFO - Running command: ['/usr/bin/bash', '-c', 'docker run -d --name sofascore_scraper_container -v C:/Users/efsta/Desktop/Kostas/Data/football_scotland/***/dags/sofascore_scraper_container/csv:/app/csv kostasmitalloulis/sofascoe_scraper_image_up:latest']
[2024-10-08T13:33:18.769+0000] {subprocess.py:86} INFO - Output:
[2024-10-08T13:33:18.789+0000] {subprocess.py:93} INFO - docker: Cannot connect to the Docker daemon at unix:///var/run/docker.sock. Is the docker daemon running?.
[2024-10-08T13:33:18.790+0000] {subprocess.py:93} INFO - See 'docker run --help'.
[2024-10-08T13:33:18.791+0000] {subprocess.py:97} INFO - Command exited with return code 125
[2024-10-08T13:33:18.792+0000] {taskinstance.py:441} INFO - ::group::Post task execution logs
[2024-10-08T13:33:18.802+0000] {taskinstance.py:2905} ERROR - Task failed with exception
Traceback (most recent call last):
  File "/home/airflow/.local/lib/python3.12/site-packages/airflow/models/taskinstance.py", line 465, in _execute_task
    result = _execute_callable(context=context, **execute_callable_kwargs)
             ^^^^^^^^^^^^^^^^^^^^^^^^^^^^^^^^^^^^^^^^^^^^^^^^^^^^^^^^^^^^^
  File "/home/airflow/.local/lib/python3.12/site-packages/airflow/models/taskinstance.py", line 432, in _execute_callable
    return execute_callable(context=context, **execute_callable_kwargs)
           ^^^^^^^^^^^^^^^^^^^^^^^^^^^^^^^^^^^^^^^^^^^^^^^^^^^^^^^^^^^^
  File "/home/airflow/.local/lib/python3.12/site-packages/airflow/models/baseoperator.py", line 401, in wrapper
    return func(self, *args, **kwargs)
           ^^^^^^^^^^^^^^^^^^^^^^^^^^^
  File "/home/airflow/.local/lib/python3.12/site-packages/airflow/operators/bash.py", line 243, in execute
    raise AirflowException(
airflow.exceptions.AirflowException: Bash command failed. The command returned a non-zero exit code 125.
[2024-10-08T13:33:18.806+0000] {taskinstance.py:1206} INFO - Marking task as FAILED. dag_id=update_database, task_id=run_sofascore_scraper, run_id=manual__2024-10-08T13:28:14.646658+00:00, execution_date=20241008T132814, start_date=20241008T133318, end_date=20241008T133318
[2024-10-08T13:33:18.819+0000] {standard_task_runner.py:110} ERROR - Failed to execute job 3811 for task run_sofascore_scraper (Bash command failed. The command returned a non-zero exit code 125.; 430)
[2024-10-08T13:33:18.842+0000] {local_task_job_runner.py:240} INFO - Task exited with return code 1
[2024-10-08T13:33:18.861+0000] {taskinstance.py:3503} INFO - 0 downstream tasks scheduled from follow-on schedule check
[2024-10-08T13:33:18.863+0000] {local_task_job_runner.py:222} INFO - ::endgroup::
